Traceback (most recent call last):
  File "C:\Users\charl\AppData\Local\Programs\Python\Python312\Lib\site-packages\urllib3\connectionpool.py", line 790, in urlopen
    response = self._make_request(
               ^^^^^^^^^^^^^^^^^^^
  File "C:\Users\charl\AppData\Local\Programs\Python\Python312\Lib\site-packages\urllib3\connectionpool.py", line 491, in _make_request
    raise new_e
  File "C:\Users\charl\AppData\Local\Programs\Python\Python312\Lib\site-packages\urllib3\connectionpool.py", line 467, in _make_request
    self._validate_conn(conn)
  File "C:\Users\charl\AppData\Local\Programs\Python\Python312\Lib\site-packages\urllib3\connectionpool.py", line 1096, in _validate_conn
    conn.connect()
  File "C:\Users\charl\AppData\Local\Programs\Python\Python312\Lib\site-packages\urllib3\connection.py", line 642, in connect
    sock_and_verified = _ssl_wrap_socket_and_match_hostname(
                        ^^^^^^^^^^^^^^^^^^^^^^^^^^^^^^^^^^^^
  File "C:\Users\charl\AppData\Local\Programs\Python\Python312\Lib\site-packages\urllib3\connection.py", line 782, in _ssl_wrap_socket_and_match_hostname
    ssl_sock = ssl_wrap_socket(
               ^^^^^^^^^^^^^^^^
  File "C:\Users\charl\AppData\Local\Programs\Python\Python312\Lib\site-packages\urllib3\util\ssl_.py", line 470, in ssl_wrap_socket
    ssl_sock = _ssl_wrap_socket_impl(sock, context, tls_in_tls, server_hostname)
               ^^^^^^^^^^^^^^^^^^^^^^^^^^^^^^^^^^^^^^^^^^^^^^^^^^^^^^^^^^^^^^^^^
  File "C:\Users\charl\AppData\Local\Programs\Python\Python312\Lib\site-packages\urllib3\util\ssl_.py", line 514, in _ssl_wrap_socket_impl
    return ssl_context.wrap_socket(sock, server_hostname=server_hostname)
           ^^^^^^^^^^^^^^^^^^^^^^^^^^^^^^^^^^^^^^^^^^^^^^^^^^^^^^^^^^^^^^
  File "C:\Users\charl\AppData\Local\Programs\Python\Python312\Lib\ssl.py", line 455, in wrap_socket
    return self.sslsocket_class._create(
           ^^^^^^^^^^^^^^^^^^^^^^^^^^^^^
  File "C:\Users\charl\AppData\Local\Programs\Python\Python312\Lib\ssl.py", line 1046, in _create
    self.do_handshake()
  File "C:\Users\charl\AppData\Local\Programs\Python\Python312\Lib\ssl.py", line 1317, in do_handshake
    self._sslobj.do_handshake()
ConnectionResetError: [WinError 10054] Une connexion existante a dû être fermée par l’hôte distant

During handling of the above exception, another exception occurred:

Traceback (most recent call last):
  File "C:\Users\charl\AppData\Local\Programs\Python\Python312\Lib\site-packages\requests\adapters.py", line 486, in send
    resp = conn.urlopen(
           ^^^^^^^^^^^^^
  File "C:\Users\charl\AppData\Local\Programs\Python\Python312\Lib\site-packages\urllib3\connectionpool.py", line 844, in urlopen
    retries = retries.increment(
              ^^^^^^^^^^^^^^^^^^
  File "C:\Users\charl\AppData\Local\Programs\Python\Python312\Lib\site-packages\urllib3\util\retry.py", line 470, in increment
    raise reraise(type(error), error, _stacktrace)
          ^^^^^^^^^^^^^^^^^^^^^^^^^^^^^^^^^^^^^^^^
  File "C:\Users\charl\AppData\Local\Programs\Python\Python312\Lib\site-packages\urllib3\util\util.py", line 38, in reraise
    raise value.with_traceback(tb)
  File "C:\Users\charl\AppData\Local\Programs\Python\Python312\Lib\site-packages\urllib3\connectionpool.py", line 790, in urlopen
    response = self._make_request(
               ^^^^^^^^^^^^^^^^^^^
  File "C:\Users\charl\AppData\Local\Programs\Python\Python312\Lib\site-packages\urllib3\connectionpool.py", line 491, in _make_request
    raise new_e
  File "C:\Users\charl\AppData\Local\Programs\Python\Python312\Lib\site-packages\urllib3\connectionpool.py", line 467, in _make_request
    self._validate_conn(conn)
  File "C:\Users\charl\AppData\Local\Programs\Python\Python312\Lib\site-packages\urllib3\connectionpool.py", line 1096, in _validate_conn
    conn.connect()
  File "C:\Users\charl\AppData\Local\Programs\Python\Python312\Lib\site-packages\urllib3\connection.py", line 642, in connect
    sock_and_verified = _ssl_wrap_socket_and_match_hostname(
                        ^^^^^^^^^^^^^^^^^^^^^^^^^^^^^^^^^^^^
  File "C:\Users\charl\AppData\Local\Programs\Python\Python312\Lib\site-packages\urllib3\connection.py", line 782, in _ssl_wrap_socket_and_match_hostname
    ssl_sock = ssl_wrap_socket(
               ^^^^^^^^^^^^^^^^
  File "C:\Users\charl\AppData\Local\Programs\Python\Python312\Lib\site-packages\urllib3\util\ssl_.py", line 470, in ssl_wrap_socket
    ssl_sock = _ssl_wrap_socket_impl(sock, context, tls_in_tls, server_hostname)
               ^^^^^^^^^^^^^^^^^^^^^^^^^^^^^^^^^^^^^^^^^^^^^^^^^^^^^^^^^^^^^^^^^
  File "C:\Users\charl\AppData\Local\Programs\Python\Python312\Lib\site-packages\urllib3\util\ssl_.py", line 514, in _ssl_wrap_socket_impl
    return ssl_context.wrap_socket(sock, server_hostname=server_hostname)
           ^^^^^^^^^^^^^^^^^^^^^^^^^^^^^^^^^^^^^^^^^^^^^^^^^^^^^^^^^^^^^^
  File "C:\Users\charl\AppData\Local\Programs\Python\Python312\Lib\ssl.py", line 455, in wrap_socket
    return self.sslsocket_class._create(
           ^^^^^^^^^^^^^^^^^^^^^^^^^^^^^
  File "C:\Users\charl\AppData\Local\Programs\Python\Python312\Lib\ssl.py", line 1046, in _create
    self.do_handshake()
  File "C:\Users\charl\AppData\Local\Programs\Python\Python312\Lib\ssl.py", line 1317, in do_handshake
    self._sslobj.do_handshake()
urllib3.exceptions.ProtocolError: ('Connection aborted.', ConnectionResetError(10054, 'Une connexion existante a dû être fermée par l’hôte distant', None, 10054, None))

During handling of the above exception, another exception occurred:

Traceback (most recent call last):
  File "C:\Users\charl\Documents\SmashPros\NaetoruOverlay\tokeep\SmashPros Overlay\assets\naeStats.py", line 71, in <module>
    stats()
  File "C:\Users\charl\Documents\SmashPros\NaetoruOverlay\tokeep\SmashPros Overlay\assets\naeStats.py", line 24, in stats
    response = requests.get(url, headers=headers)
               ^^^^^^^^^^^^^^^^^^^^^^^^^^^^^^^^^^
  File "C:\Users\charl\AppData\Local\Programs\Python\Python312\Lib\site-packages\requests\api.py", line 73, in get
    return request("get", url, params=params, **kwargs)
           ^^^^^^^^^^^^^^^^^^^^^^^^^^^^^^^^^^^^^^^^^^^^
  File "C:\Users\charl\AppData\Local\Programs\Python\Python312\Lib\site-packages\requests\api.py", line 59, in request
    return session.request(method=method, url=url, **kwargs)
           ^^^^^^^^^^^^^^^^^^^^^^^^^^^^^^^^^^^^^^^^^^^^^^^^^
  File "C:\Users\charl\AppData\Local\Programs\Python\Python312\Lib\site-packages\requests\sessions.py", line 589, in request
    resp = self.send(prep, **send_kwargs)
           ^^^^^^^^^^^^^^^^^^^^^^^^^^^^^^
  File "C:\Users\charl\AppData\Local\Programs\Python\Python312\Lib\site-packages\requests\sessions.py", line 703, in send
    r = adapter.send(request, **kwargs)
        ^^^^^^^^^^^^^^^^^^^^^^^^^^^^^^^
  File "C:\Users\charl\AppData\Local\Programs\Python\Python312\Lib\site-packages\requests\adapters.py", line 501, in send
    raise ConnectionError(err, request=request)
requests.exceptions.ConnectionError: ('Connection aborted.', ConnectionResetError(10054, 'Une connexion existante a dû être fermée par l’hôte distant', None, 10054, None))
